Workbook

Sheet 00_Инструкция
A1: Инвестиционная модель проекта «1С:Кабинет сотрудника» — инструкция
A3: Назначение
A4: Модель для защиты инвестиций: рынок (TAM–SAM–SOM), сегментация клиентской базы, план/факт продаж, P&L и ДДС. Все вводимые параметры — только на листе «01_Исходные_данные».
A6: Цветовая легенда
A7: Зелёные ячейки — ввод данных | C7: Меняйте только их
A8: Серые ячейки — формулы | C8: Не редактировать
A9: Красные ячейки — контрольные показатели | C9: KPI / точка безубыточности / алерты
A11: Что вводится вручную
A12: • Стоимость лицензии / закупка 1С
A13: • Количество менеджеров и оклады
A14: • Размер премии по сценариям
A15: • Плановые конверсии воронки (гипотезы)
A16: • Целевые продажи на менеджера (4 / 6 / 9)
A17: • Маркетинг и прочие расходы
A18: • Факт воронки: обработано → переговоры → демо → сделка → оплата
A19: • Уточнение ССЧР / ОКВЭД в базе (если есть свежие данные)
A21: Что считается автоматически
A22: • Конверсии этапов и общая конверсия
A23: • Продажи, выручка, маржа, премии
... A39: ССЧР подтянуты из открытых данных ФНС (набор 7707329152-sshr2019, данные за 2025). ОКВЭД — из выписок ЕГРЮЛ. Покрытие неполное: ИП и часть ЮЛ могут отсутствовать в открытых наборах. Не экстраполируйте подтверждённый сегмент на всю базу без оговорок.

Sheet 11_Dashboard
A1: Dashboard инвестора — «1С:Кабинет сотрудника»
A2: Все KPI связаны с исходными данными, базой, планом и фактом. Меняйте только зелёные поля на листе исходных данных и факта.
A4: Показатель | B4: Значение | C4: Ед. | E4: Продажи и финансы (средний план / факт)
A5: Уникальных клиентов | B5: ='01_Исходные_данные'!B41 | C5: шт. | E5: Показатель | F5: План (средний) | G5: Факт
A6: С целевым ОКВЭД | B6: ='01_Исходные_данные'!B44 | C6: шт. | E6: План/факт оплат | F6: ='07_План_продаж'!C12 | G6: ='08_Факт_воронка'!H8
A7: С численностью 22+ | B7: ='01_Исходные_данные'!B45 | C7: шт. | E7: Выручка | F7: ='07_План_продаж'!D12 | G7: ='08_Факт_воронка'!O8
A8: Горячие (приоритет №1 / 50+) | B8: ='01_Исходные_данные'!B47 | C8: шт. | E8: Маржа | F8: ='07_План_продаж'!E12 | G8: ='08_Факт_воронка'!P8
A9: Горячие на листе менеджеров | B9: 345 | C9: шт. | E9: Прибыль (P&L) | F9: ='09_PnL'!C13 | G9: ='09_PnL'!E13
A10: Покрытие ССЧР | B10: ='01_Исходные_данные'!B51 | C10: % | E10: Выполнение плана | F10: — | G10: ='08_Факт_воронка'!N8
A11: Покрытие ОКВЭД | B11: ='01_Исходные_данные'!B52 | C11: % | E11: Общая конверсия факт | F11: — | G11: ='08_Факт_воронка'!M8
E12: Денежный поток | F12: ='10_ДДС'!H7 | G12: ='10_ДДС'!B31
A13: Рынок
A14: TAM ₽/год | B14: ='03_TAM_SAM_SOM'!D5 | E14: Unit-экономика
A15: SAM ₽/год | B15: ='03_TAM_SAM_SOM'!D6 | E15: Цена | F15: ='01_Исходные_данные'!B5
A16: SOM capacity (средний) ₽/год | B16: ='03_TAM_SAM_SOM'!E13 | E16: Маржа / клиент | F16: ='01_Исходные_данные'!B7
A17: Подтверждённая база ₽/год | B17: ='03_TAM_SAM_SOM'!D8 | E17: Маржинальность | F17: ='01_Исходные_данные'!B8
E18: Безубыточность, оплат/мес | F18: ='10_ДДС'!B10
E19: Средний чек горячих (по пакетам) | F19: 53464
A20: План команды по сценариям | E20: Заметка | F20: План 4/6/9 сейчас считает старт 3 360 ₽. Для защиты покажите также сценарий со средним чеком горячих.
A21: Сценарий | B21: Продаж/мес | C21: Выручка | D21: Маржа | E21: Опер. результат
A22: ='07_План_продаж'!A11 | B22: ='07_План_продаж'!C11 | C22: ='07_План_продаж'!D11 | D22: ='07_План_продаж'!E11 | E22: ='07_План_продаж'!H11
A23: ='07_План_продаж'!A12 | B23: ='07_План_продаж'!C12 | C23: ='07_План_продаж'!D12 | D23: ='07_План_продаж'!E12 | E23: ='07_План_продаж'!H12
A24: ='07_План_продаж'!A13 | B24: ='07_План_продаж'!C13 | C24: ='07_План_продаж'!D13 | D24: ='07_План_продаж'!E13 | E24: ='07_План_продаж'!H13
A26: Контроль качества модели
A27: ССЧР обогащено у 1564 из 7318 уникальных ИНН; ОКВЭД — у 344. Для защиты используйте подтверждённый минимум и capacity-based SOM, пока SAM не заполнен федеральным срезом.

Sheet 01_Исходные_данные
A1: Исходные данные — единственная точка ввода параметров модели
A2: Зелёные — ввод. Серые — формулы. Красные — контрольные. Любое изменение пересчитывает всю модель.
A4: A. Продукт и unit-экономика
A5: Цена годовой подписки (старт до 10) | B5: 3360 | C5: ₽/год | D5: Розница; стартовый пакет
A6: Закупка 1С (партнёрская) | B6: 1680 | C6: ₽/год | D6: Дилерская цена
A7: Маржинальный доход / клиент | B7: =B5-B6 | C7: ₽/год | D7: Цена − закупка
A8: Маржинальность до продажных расходов | B8: =IF(B5=0,0,B7/B5) | C8: % | D8: Маржа / цена
A9: Порог «горячий» по численности | B9: 22 | C9: чел. | D9: ОКВЭД + N+
A10: Порог стратегический по численности | B10: 50 | C10: чел. | D10: 50+ = горячий даже без ОКВЭД
A12: B. Воронка и планы (гипотезы — не факт)
A13: Показатель | B13: Малый | C13: Средний | D13: Большой | E13: Ед. | F13: Комментарий
A14: Лиды / менеджер / месяц | B14: 150 | C14: 150 | D14: 150 | E14: шт. | F14: Гипотеза загрузки
A15: Обработка → переговоры | B15: 0.25 | C15: 0.3 | D15: 0.35 | E15: % | F15: Гипотеза; факт — на листе воронки
A16: Переговоры → демо | B16: 0.4 | C16: 0.45 | D16: 0.5 | E16: % | F16: Гипотеза
A17: Демо → сделка | B17: 0.45 | C17: 0.5 | D17: 0.55 | E17: % | F17: Гипотеза
A18: Сделка → оплата | B18: 0.8 | C18: 0.85 | D18: 0.9 | E18: % | F18: Гипотеза
A19: Общая конверсия лид → оплата | B19: =B15*B16*B17*B18 | C19: =C15*C16*C17*C18 | D19: =D15*D16*D17*D18 | E19: % | F19: Автоматический расчёт
A20: Целевые продажи / менеджер / месяц | B20: 4 | C20: 6 | D20: 9 | E20: шт. | F20: Коммерческий план 4/6/9
A22: C. Премии (% от маржинального дохода)
A23: Показатель | B23: Малый | C23: Средний | D23: Большой | E23: Ед. | F23: Комментарий
A24: Премия от маржи | B24: 0.2 | C24: 0.3 | D24: 0.35 | E24: % | F24: От маржинального дохода, не от выручки
A26: D. Команда и расходы
A27: Менеджер | B27: Оклад ₽/мес. | C27: Активен | D27: Примечание
A28: Оглоблина | B28: 50400 | C28: Да
A29: Юнусова | B29: 50400 | C29: Да
A30: Кургузов | B30: 51200 | C30: Да
A31: Количество активных менеджеров | B31: =COUNTIF(C28:C30,"Да")
A32: Сумма окладов активных | B32: =SUMIF(C28:C30,"Да",B28:B30)
A33: Маркетинг и реклама, ₽/мес. | B33: 0
A34: Техподдержка / сопровождение, ₽/мес. | B34: 0
A35: Прочие расходы, ₽/мес. | B35: 0
A37: E. Рынок и качество клиентской базы (автоиз базы + ручные рыночные вводы)
A38: Показатель | B38: Значение | C38: Ед. | D38: Источник / статус
A39: Все организации РФ (ориентир) | B39: 3139000 | C39: шт. | D39: Верхняя граница; НЕ целевой TAM продукта
A40: Записей с ИНН в нашей базе | B40: 7944 | C40: шт. | D40: Факт базы
A41: Уникальных ИНН | B41: 7318 | C41: шт. | D41: Дедупликация
A42: Уникальных ИНН с ССЧР | B42: 1564 | C42: шт. | D42: ФНС открытые данные
A43: Уникальных ИНН с ОКВЭД | B43: 344 | C43: шт. | D43: ЕГРЮЛ
A44: Целевой ОКВЭД (подтверждено) | B44: 341 | C44: шт. | D44: По списку ICP
A45: Численность ≥22 | B45: 351 | C45: шт. | D45: Порог из B9
...

Sheet 02_Тарифы
A1: Тарифы «1С:Кабинет сотрудника»
A2: Источник: прайс партнёра (розница / дилер). Стартовый оффер модели — пакет до 10.
A4: Пакет | B4: Сотрудников до | C4: Цена ₽/мес. | D4: Цена ₽/год | E4: Закупка ₽/год | F4: Маржа ₽/год | G4: Маржинальность | H4: Стартовый?
A5: До 10 | B5: 10 | C5: 280 | D5: 3360 | E5: 1680 | F5: =D5-E5 | G5: =IF(D5=0,0,F5/D5) | H5: Да
A6: До 25 | B6: 25 | C6: 700 | D6: 8400 | E6: 4200 | F6: =D6-E6 | G6: =IF(D6=0,0,F6/D6) | H6: Нет
A7: До 50 | B7: 50 | C7: 1400 | D7: 16800 | E7: 8400 | F7: =D7-E7 | G7: =IF(D7=0,0,F7/D7) | H7: Нет
A8: До 100 | B8: 100 | C8: 2800 | D8: 33600 | E8: 16800 | F8: =D8-E8 | G8: =IF(D8=0,0,F8/D8) | H8: Нет
A9: До 200 | B9: 200 | C9: 5200 | D9: 62400 | E9: 31200 | F9: =D9-E9 | G9: =IF(D9=0,0,F9/D9) | H9: Нет
A10: До 500 | B10: 500 | C10: 12000 | D10: 144000 | E10: 72000 | F10: =D10-E10 | G10: =IF(D10=0,0,F10/D10) | H10: Нет
A11: До 2000 | B11: 2000 | C11: 48000 | D11: 528000 | E11: 264000 | F11: =D11-E11 | G11: =IF(D11=0,0,F11/D11) | H11: Нет
A12: До 5000 | B12: 5000 | C12: 115000 | D12: 1260000 | E12: 630000 | F12: =D12-E12 | G12: =IF(D12=0,0,F12/D12) | H12: Нет
A14: Логика КП: старт — до 10 сотрудников (3 360 ₽/год). После пилота — пакет по фактической численности.
A15: Потенциал по базе считается по ближайшему достаточному пакету из этой таблицы.

Sheet 03_TAM_SAM_SOM
A1: TAM — SAM — SOM: рынок для инвестора
A2: Общий рынок организаций РФ ≠ целевой рынок. SAM заполняется после федерального среза по ОКВЭД. SOM — capacity команды.
A4: Показатель | B4: Организаций | C4: Годовой чек ₽ | D4: Объём ₽/год | E4: Доля | F4: Источник / статус
A5: TAM (верхняя граница: все орг. РФ) | B5: ='01_Исходные_данные'!B39 | C5: ='01_Исходные_данные'!B5 | D5: =B5*C5 | E5: 1 | F5: Ориентир; не доказанный TAM продукта КЭДО
A6: SAM — целевые ОКВЭД | B6: ='01_Исходные_данные'!B53 | C6: ='01_Исходные_данные'!B5 | D6: =IF(B6="","" ,B6*C6) | E6: =IF(OR(B6="",B5=0),"",B6/B5) | F6: Введите число в Исходных данных после cross-join
A7: SAM — целевые ОКВЭД + 22+ | B7: ='01_Исходные_данные'!B54 | C7: ='01_Исходные_данные'!B5 | D7: =IF(B7="","" ,B7*C7) | E7: =IF(OR(B7="",B5=0),"",B7/B5) | F7: Узкий SAM по ICP
A8: Подтверждённая целевая база (наша) | B8: ='01_Исходные_данные'!B50 | C8: ='01_Исходные_данные'!B5 | D8: =B8*C8 | E8: =IF(B5=0,0,B8/B5) | F8: Факт нашей базы после обогащения
A10: SOM — capacity-based (мощность команды)
A11: Сценарий | B11: Менеджеров | C11: Продаж/мен/мес | D11: Продаж/год | E11: Выручка/год | F11: Доля от TAM | G11: Комментарий
A12: Малый | B12: ='01_Исходные_данные'!B31 | C12: ='01_Исходные_данные'!B20 | D12: =B12*C12*12 | E12: =D12*'01_Исходные_данные'!B5 | F12: =IF(D5=0,0,E12/D5) | G12: Ограничение — мощность команды
A13: Средний | B13: ='01_Исходные_данные'!B31 | C13: ='01_Исходные_данные'!C20 | D13: =B13*C13*12 | E13: =D13*'01_Исходные_данные'!B5 | F13: =IF(D5=0,0,E13/D5) | G13: Ограничение — мощность команды
A14: Большой | B14: ='01_Исходные_данные'!B31 | C14: ='01_Исходные_данные'!D20 | D14: =B14*C14*12 | E14: =D14*'01_Исходные_данные'!B5 | F14: =IF(D5=0,0,E14/D5) | G14: Ограничение — мощность команды
A16: SOM — market-based (если заполнен SAM)
A17: Доля проникновения | B17: SAM ₽/год | C17: SOM ₽/год | D17: SOM клиентов | E17: Смысл
A18: 0.005 | B18: =D6 | C18: =IF(B18="","",B18*A18) | D18: =IF(OR(C18="",'01_Исходные_данные'!B5=0),"",C18/'01_Исходные_данные'!B5) | E18: Сценарная доля SAM
A19: 0.01 | B19: =D6 | C19: =IF(B19="","",B19*A19) | D19: =IF(OR(C19="",'01_Исходные_данные'!B5=0),"",C19/'01_Исходные_данные'!B5) | E19: Сценарная доля SAM
A20: 0.02 | B20: =D6 | C20: =IF(B20="","",B20*A20) | D20: =IF(OR(C20="",'01_Исходные_данные'!B5=0),"",C20/'01_Исходные_данные'!B5) | E20: Сценарная доля SAM
A22: Как читать для инвестора
A23: TAM — потолок рынка. SAM — компании с нужным ОКВЭД/ICP. SOM — что реально взять мощностью 3 менеджеров при плане 4/6/9.
A24: Пока SAM пуст — опирайтесь на capacity-based SOM и подтверждённую целевую базу (строка 8).

Sheet 04_Сегменты_базы
A1: Анализ клиентской базы — три сегмента
A2: 1) Целевой ОКВЭД. 2) Численность 22+. 3) Пересечение ОКВЭД + 22+ (приоритет №1). Сегменты взаимоисключающие в приоритетах.
A4: Приоритет | B4: Критерий | C4: Уникальных ИНН | D4: Доля базы | E4: Потенциал ₽/год (старт 3360) | F4: Потенциал по пакетам (если есть ССЧР) | G4: Действие
A5: 1 — Горячие | B5: ОКВЭД + 22+ или 50+ | C5: ='01_Исходные_данные'!B47 | D5: =IF('01_Исходные_данные'!B41=0,0,C5/'01_Исходные_данные'!B41) | E5: =C5*'01_Исходные_данные'!B5 | F5: 18445200 | G5: Обрабатывать первыми; персональный оффер
A6: 2 — Целевой ОКВЭД | B6: Целевой ОКВЭД, 22+ не подтверждён | C6: ='01_Исходные_данные'!B48 | D6: =IF('01_Исходные_данные'!B41=0,0,C6/'01_Исходные_данные'!B41) | E6: =C6*'01_Исходные_данные'!B5 | F6: 0 | G6: Обогащать ССЧР и запускать продажи
A7: 3 — Дополнительный | B7: 22+ без целевого ОКВЭД | C7: ='01_Исходные_данные'!B49 | D7: =IF('01_Исходные_данные'!B41=0,0,C7/'01_Исходные_данные'!B41) | E7: =C7*'01_Исходные_данные'!B5 | F7: 100800 | G7: Тестировать отдельным сценарием
A8: ИТОГО целевая | B8: Объединение сегментов | C8: ='01_Исходные_данные'!B50 | D8: =IF('01_Исходные_данные'!B41=0,0,C8/'01_Исходные_данные'!B41) | E8: =C8*'01_Исходные_данные'!B5 | F8: =SUM(F5:F7) | G8: Подтверждённый минимум для плана
A10: Контроль качества обогащения
A11: Покрытие ССЧР | B11: ='01_Исходные_данные'!B51
A12: Покрытие ОКВЭД | B12: ='01_Исходные_данные'!B52
A13: Если покрытие низкое — в инвестпрезентации показывайте подтверждённый минимум и отдельно план обогащения, а не экстраполяцию на все уникальные ИНН.

Sheet 05_База_клиентов
A1: База клиентов — сегментация по ОКВЭД и численности
A2: Автоматически: целевой ОКВЭД / 22+ / пересечение (приоритет №1). ССЧР — открытые данные ФНС; ОКВЭД — выписки ЕГРЮЛ. Зелёные поля можно уточнять вручную.
A3: Не удаляйте формулы в столбцах K–O и T–X. Ввод: G, H, I, J и комментарии.
A4: Регномер | B4: Клиент | C4: ИНН / ЕДРПОУ из базы | D4: ИНН | E4: Тип ИНН | F4: Комментарий из исходной базы | G4: Численность сотрудников (ССЧР) | H4: Год ССЧР | I4: Основной ОКВЭД | J4: Все ОКВЭД | K4: Подходит по численности ≥22? | L4: Подходит по целевому ОКВЭД? | M4: Пакет КС | N4: Потенциальная выручка/год, ₽ | O4: Категория по численности | P4: Статус проверки | Q4: Источник ССЧР | R4: Источник ОКВЭД | S4: Уникальный по ИНН | T4: Приоритет | U4: Сегмент | V4: ОКВЭД подходит? | W4: Численность подходит? | X4: ОКВЭД + численность (приоритет №1)
A5: 801618911 | B5: ООО "Профимед" | C5: 3801001629 | D5: 3801001629 | E5: ЮЛ РФ | F5: под эпд подходит, ндз, ндз2, ндз3 | G5: 17 | H5: 2025 | K5: Нет | L5: Не определено | M5: До 25 | N5: 8400 | O5: 16–30 | P5: ССЧР обогащена; ОКВЭД не найден/не загружен | Q5: ФНС открытые данные ССЧР (ДатаСост 31.12.2025; набор 7707329152-sshr2019) | R5: =HYPERLINK("https://checko.ru/search?query=3801001629","Чекко: проверить") | S5: 1 | T5: 4 — Не обогащён | U5: Нет ОКВЭД/ССЧР | V5: Не определено | W5: Нет
A6: 801621098 | B6: МАНО "ЦДС" | C6: 3801075684 | D6: 3801075684 | E6: ЮЛ РФ | L6: Не определено | P6: Требует обогащения | Q6: =HYPERLINK("https://pb.nalog.ru/search.html?query=3801075684","ФНС: проверить") | R6: =HYPERLINK("https://checko.ru/search?query=3801001629","Чекко: проверить") | S6: 1 | T6: 4 — Не обогащён | U6: Нет ОКВЭД/ССЧР | V6: Не определено
A7: 804704363 | B7: Индивидуальный Предприниматель Клычкова Алина Николаевна | C7: 143400403400 | D7: 143400403400 | E7: ИП РФ / физлицо | F7: себеи возят сами | L7: Не определено | P7: Требует обогащения | Q7: =HYPERLINK("https://pb.nalog.ru/search.html?query=143400403400","ФНС: проверить") | R7: =HYPERLINK("https://checko.ru/search?query=3801001629","Чекко: проверить") | S7: 1 | T7: 4 — Не обогащён | U7: Нет ОКВЭД/ССЧР | V7: Не определено
A8: 800404718 | B8: МРО Православный приход храма всех святых г. Братска | C8: 3803200965 | D8: 3803200965 | E8: ЮЛ РФ | L8: Не определено | P8: Требует обогащения | Q8: =HYPERLINK("https://pb.nalog.ru/search.html?query=3803200965","ФНС: проверить") | R8: =HYPERLINK("https://checko.ru/search?query=3801001629","Чекко: проверить") | S8: 1 | T8: 4 — Не обогащён | U8: Нет ОКВЭД/ССЧР | V8: Не определено
A9: 9975531 | B9: ООО "БайкалВЭД" | C9: 3808224590 | D9: 3808224590 | E9: ЮЛ РФ | F9: со сбисом | G9: 22 | H9: 2025 | I9: 16.23 | J9: 16.23; 46.13; 46.73; 46.73.1; 46.73.2; 46.73.6; 47.52.71; 49.41; 49.42; 52.10; 52.24 | K9: Да | L9: Да | M9: До 25 | N9: 8400 | O9: 16–30 | P9: ССЧР + ОКВЭД обогащены | Q9: ФНС открытые данные ССЧР (ДатаСост 31.12.2025; набор 7707329152-sshr2019) | R9: ЕГРЮЛ / egrul.nalog.ru (выписка) | S9: 1 | T9: 1 — Горячий | U9: ОКВЭД + 22+ | V9: Да | W9: Да | X9: Да
A10: 800771347 | B10: ИП Колесников Юрий Владимирович | C10: 380500038435 | D10: 380500038435 | E10: ИП РФ / физлицо | F10: контур, на почте посмотрит доки и 1с эпд | L10: Не определено | P10: Требует обогащения | Q10: =HYPERLINK("https://pb.nalog.ru/search.html?query=380500038435","ФНС: проверить") | R10: =HYPERLINK("https://checko.ru/search?query=3801001629","Чекко: проверить") | S10: 1 | T10: 4 — Не обогащён | U10: Нет ОКВЭД/ССЧР | V10: Не определено
A11: 800448230 | B11: Ротонда | C11: 3812145125 | D11: 3812145125 | E11: ЮЛ РФ | F11: . контакты неактуальные | G11: 1 | H11: 2025 | K11: Нет | L11: Не определено | M11: До 10 | N11: 3360 | O11: 1–15 | P11: ССЧР обогащена; ОКВЭД не найден/не загружен | Q11: ФНС открытые данные ССЧР (ДатаСост 31.12.2025; набор 7707329152-sshr2019) | R11: =HYPERLINK("https://checko.ru/search?query=3801001629","Чекко: проверить") | S11: 1 | T11: 4 — Не обогащён | U11: Нет ОКВЭД/ССЧР | V11: Не определено | W11: Нет
A12: 800385156 | B12: ООО "ИРК.РУ" | C12: 3808082842 | D12: 3808082842 | E12: ЮЛ РФ | F12: оквед реклама | G12: 18 | H12: 2025 | K12: Нет | L12: Не определено | M12: До 25 | N12: 8400 | O12: 16–30 | P12: ССЧР обогащена; ОКВЭД не найден/не загружен | Q12: ФНС открытые данные ССЧР (ДатаСост 31.12.2025; набор 7707329152-sshr2019) | R12: =HYPERLINK("https://checko.ru/search?query=3801001629","Чекко: проверить") | S12: 1 | T12: 4 — Не обогащён | U12: Нет ОКВЭД/ССЧР | V12: Не определено | W12: Нет
A13: 804170177 | B13: ООО "ДЭП №153" | C13: 3814019503 | D13: 3814019503 | E13: ЮЛ РФ | F13: не работают с трн | G13: 221 | H13: 2025 | I13: 42.11 | J13: 42.11; 08.12.1; 23.99; 52.21.22; 08.11; 08.12; 19.20; 23.63; 23.99.2; 23.99.3; 41.20; 42.13; 42.99; 46.90 | K13: Да | L13: Да | M13: До 500 | N13: 144000 | O13: 201–500 | P13: ССЧР + ОКВЭД обогащены | Q13: ФНС открытые данные ССЧР (ДатаСост 31.12.2025; набор 7707329152-sshr2019) | R13: ЕГРЮЛ / egrul.nalog.ru (выписка) | S13: 1 | T13: 1 — Горячий | U13: ОКВЭД + 22+ | V13: Да | W13: Да | X13: Да
A14: 801820675 | B14: ООО "РИВЬЕРА" | C14: 2407012902 | D14: 2407012902 | E14: ЮЛ РФ | F14: оквед аренда | G14: 1 | H14: 2025 | K14: Нет | L14: Не определено | M14: До 10 | N14: 3360 | O14: 1–15 | P14: ССЧР обогащена; ОКВЭД не найден/не загружен | Q14: ФНС открытые данные ССЧР (ДатаСост 31.12.2025; набор 7707329152-sshr2019) | R14: =HYPERLINK("https://checko.ru/search?query=3801001629","Чекко: проверить") | S14: 1 | T14: 4 — Не обогащён | U14: Нет ОКВЭД/ССЧР | V14: Не определено | W14: Нет
A15: 804690915 | B15: ООО ПЭД | C15: 3849067730 | D15: 3849067730 | E15: ЮЛ РФ | F15: подходят ндз, не исп тр накладные | G15: 1 | H15: 2025 | K15: Нет | L15: Не определено | M15: До 10 | N15: 3360 | O15: 1–15 | P15: ССЧР обогащена; ОКВЭД не найден/не загружен | Q15: ФНС открытые данные ССЧР (ДатаСост 31.12.2025; набор 7707329152-sshr2019) | R15: =HYPERLINK("https://checko.ru/search?query=3801001629","Чекко: проверить") | S15: 1 | T15: 4 — Не обогащён | U15: Нет ОКВЭД/ССЧР | V15: Не определено | W15: Нет
A16: 9146873 | B16: ООО "Саянск-Лифт" | C16: 3814008565 | D16: 3814008565 | E16: ЮЛ РФ | F16: ответили на почту отпр, свяжутся сами | G16: 25 | H16: 2025 | I16: 43.29 | J16: 43.29; 68.32.1 | K16: Да | L16: Да | M16: До 25 | N16: 8400 | O16: 16–30 | P16: ССЧР + ОКВЭД обогащены | Q16: ФНС открытые данные ССЧР (ДатаСост 31.12.2025; набор 7707329152-sshr2019) | R16: ЕГРЮЛ / egrul.nalog.ru (выписка) | S16: 1 | T16: 1 — Горячий | U16: ОКВЭД + 22+ | V16: Да | W16: Да | X16: Да
A17: 20015402932 | B17: ООО "Сетевая компания «ЭнергоСервис" | C17: 3849055703 | D17: 3849055703 | E17: ЮЛ РФ | F17: не работают с трн | G17: 3 | H17: 2025 | K17: Нет | L17: Не определено | M17: До 10 | N17: 3360 | O17: 1–15 | P17: ССЧР обогащена; ОКВЭД не найден/не загружен | Q17: ФНС открытые данные ССЧР (ДатаСост 31.12.2025; набор 7707329152-sshr2019) | R17: =HYPERLINK("https://checko.ru/search?query=3801001629","Чекко: проверить") | S17: 1 | T17: 4 — Не обогащён | U17: Нет ОКВЭД/ССЧР | V17: Не определено | W17: Нет
A18: 9875412 | B18: ООО "ИНФОТЕХ" | C18: 3811442862 | D18: 3811442862 | E18: ЮЛ РФ | F18: оквед не тот | G18: 9 | H18: 2025 | K18: Нет | L18: Не определено | M18: До 10 | N18: 3360 | O18: 1–15 | P18: ССЧР обогащена; ОКВЭД не найден/не загружен | Q18: ФНС открытые данные ССЧР (ДатаСост 31.12.2025; набор 7707329152-sshr2019) | R18: =HYPERLINK("https://checko.ru/search?query=3801001629","Чекко: проверить") | S18: 1 | T18: 4 — Не обогащён | U18: Нет ОКВЭД/ССЧР | V18: Не определено | W18: Нет
A19: 9707072 | B19: ООО "БАЙКАЛБИЗНЕСБАЛАНС" | C19: 3811143943 | D19: 3811143943 | E19: ЮЛ РФ | F19: оквед не тот | G19: 3 | H19: 2025 | K19: Нет | L19: Не определено | M19: До 10 | N19: 3360 | O19: 1–15 | P19: ССЧР обогащена; ОКВЭД не найден/не загружен | Q19: ФНС открытые данные ССЧР (ДатаСост 31.12.2025; набор 7707329152-sshr2019) | R19: =HYPERLINK("https://checko.ru/search?query=3801001629","Чекко: проверить") | S19: 1 | T19: 4 — Не обогащён | U19: Нет ОКВЭД/ССЧР | V19: Не определено | W19: Нет
A20: 9893586 | B20: Первичная профсоюзная организация Иркутской государственной ордена "Знак почета" областной клинической больницы | C20: 3812054703 | D20: 3812054703 | E20: ЮЛ РФ | F20: . профсоюз | L20: Не определено | P20: Требует обогащения | Q20: =HYPERLINK("https://pb.nalog.ru/search.html?query=3812054703","ФНС: проверить") | R20: =HYPERLINK("https://checko.ru/search?query=3801001629","Чекко: проверить") | S20: 1 | T20: 4 — Не обогащён | U20: Нет ОКВЭД/ССЧР | V20: Не определено
A21: 9802010 | B21: ООО "Прибайкальская электросетевая компания" | C21: 3827032533 | D21: 3827032533 | E21: ЮЛ РФ | F21: подходят ндз, нет воз связаться | G21: 5 | H21: 2025 | K21: Нет | L21: Не определено | M21: До 10 | N21: 3360 | O21: 1–15 | P21: ССЧР обогащена; ОКВЭД не найден/не загружен | Q21: ФНС открытые данные ССЧР (ДатаСост 31.12.2025; набор 7707329152-sshr2019) | R21: =HYPERLINK("https://checko.ru/search?query=3801001629","Чекко: проверить") | S21: 1 | T21: 4 — Не обогащён | U21: Нет ОКВЭД/ССЧР | V21: Не определено | W21: Нет
A22: 804668076 | B22: ООО "Экспортлес" | C22: 381109954 | D22: 3811099540 | E22: ЮЛ РФ | F22: не работают с трн | G22: 2 | H22: 2025 | K22: Нет | L22: Не определено | M22: До 10 | N22: 3360 | O22: 1–15 | P22: ССЧР обогащена; ОКВЭД не найден/не загружен | Q22: ФНС открытые данные ССЧР (ДатаСост 31.12.2025; набор 7707329152-sshr2019) | R22: =HYPERLINK("https://checko.ru/search?query=3801001629","Чекко: проверить") | S22: 1 | T22: 4 — Не обогащён | U22: Нет ОКВЭД/ССЧР | V22: Не определено | W22: Нет
A23: 800545533 | B23: АО "Облако" | C23: 3812127687 | D23: 3812127687 | E23: ЮЛ РФ | F23: оквед не тот | G23: 16 | H23: 2025 | K23: Нет | L23: Не определено | M23: До 25 | N23: 8400 | O23: 16–30 | P23: ССЧР обогащена; ОКВЭД не найден/не загружен | Q23: ФНС открытые данные ССЧР (ДатаСост 31.12.2025; набор 7707329152-sshr2019) | R23: =HYPERLINK("https://checko.ru/search?query=3801001629","Чекко: проверить") | S23: 1 | T23: 4 — Не обогащён | U23: Нет ОКВЭД/ССЧР | V23: Не определено | W23: Нет
A24: 9252299 | B24: Жилищное хозяйство ООО | C24: 1434045790 | D24: 1434045790 | E24: ЮЛ РФ | F24: ндз, ндз2, ндз3 | G24: 17 | H24: 2025 | K24: Нет | L24: Не определено | M24: До 25 | N24: 8400 | O24: 16–30 | P24: ССЧР обогащена; ОКВЭД не найден/не загружен | Q24: ФНС открытые данные ССЧР (ДатаСост 31.12.2025; набор 7707329152-sshr2019) | R24: =HYPERLINK("https://checko.ru/search?query=3801001629","Чекко: проверить") | S24: 1 | T24: 4 — Не обогащён | U24: Нет ОКВЭД/ССЧР | V24: Не определено | W24: Нет
A25: 802460214 | B25: ИП Чубаков Руслан Валерьевич | C25: 382552017976 | D25: 382552017976 | E25: ИП РФ / физлицо | F25: оквед не тот | L25: Не определено | P25: Требует обогащения | Q25: =HYPERLINK("https://pb.nalog.ru/search.html?query=382552017976","ФНС: проверить") | R25: =HYPERLINK("https://checko.ru/search?query=3801001629","Чекко: проверить") | S25: 1 | T25: 4 — Не обогащён | U25: Нет ОКВЭД/ССЧР | V25: Не определено
A26: 802463325 | B26: ООО "ТЕРМИНАЛ ЛЕНАРЕЧТРАНС" | C26: 3818043360 | D26: 3818043360 | E26: ЮЛ РФ | F26: у них контур логистика | G26: 248 | H26: 2025 | I26: 50.40.1 | J26: 50.40.1; 49.41.1; 52.10.9; 52.24.2; 46.13.1; 46.73.1; 46.73.2; 47.52.71; 49.41.2; 49.41.3; 50.30.2; 50.40; 50.40.2; 52.10; 52.21; 52.22.2; 52.24; 52.24.1; 52.29 | K26: Да | L26: Да | M26: До 500 | N26: 144000 | O26: 201–500 | P26: ССЧР + ОКВЭД обогащены | Q26: ФНС открытые данные ССЧР (ДатаСост 31.12.2025; набор 7707329152-sshr2019) | R26: ЕГРЮЛ / egrul.nalog.ru (выписка) | S26: 1 | T26: 1 — Горячий | U26: ОКВЭД + 22+ | V26: Да | W26: Да | X26: Да
A27: 800471226 | B27: ООО Сектор | C27: 3821015010 | D27: 3821015010 | E27: ЮЛ РФ | F27: не исп тр накладные | G27: 4 | H27: 2025 | K27: Нет | L27: Не определено | M27: До 10 | N27: 3360 | O27: 1–15 | P27: ССЧР обогащена; ОКВЭД не найден/не загружен | Q27: ФНС открытые данные ССЧР (ДатаСост 31.12.2025; набор 7707329152-sshr2019) | R27: =HYPERLINK("https://checko.ru/search?query=3801001629","Чекко: проверить") | S27: 1 | T27: 4 — Не обогащён | U27: Нет ОКВЭД/ССЧР | V27: Не определено | W27: Нет
A28: 9832968 | B28: ООО "Электро Мотор Ремонт" | C28: 3804042888 | D28: 3804042888 | E28: ЮЛ РФ | F28: оквед не тот | G28: 23 | H28: 2025 | I28: 33.14 | J28: 33.14; 33.12; 33.20; 35.12; 43.21; 71.20.3; 71.20.4; 71.20.9 | K28: Да | L28: Да | M28: До 25 | N28: 8400 | O28: 16–30 | P28: ССЧР + ОКВЭД обогащены | Q28: ФНС открытые данные ССЧР (ДатаСост 31.12.2025; набор 7707329152-sshr2019) | R28: ЕГРЮЛ / egrul.nalog.ru (выписка) | S28: 1 | T28: 1 — Горячий | U28: ОКВЭД + 22+ | V28: Да | W28: Да | X28: Да
A29: 802298111 | B29: ООО "СТАТУССИБ" | C29: 3827014037 | D29: 3827014037 | E29: ЮЛ РФ | F29: перезвонить марианне, выставила счет | G29: 433 | H29: 2025 | I29: 42.11 | J29: 42.11; 02.10; 02.20; 16.10; 16.10.9; 16.23.1; 31.09; 38.32.2; 38.32.3; 38.32.4; 41.20; 42.13; 43.39; 43.99.7; 46.49; 46.90; 47.30; 47.78.9; 47.79.3; 52.21.22; 52.21.23; 56.10; 56.10.1; 56.10.3; 70.22; 77.11; 77.12; 79.11; 82.99 | K29: Да | L29: Да | M29: До 500 | N29: 144000 | O29: 201–500 | P29: ССЧР + ОКВЭД обогащены | Q29: ФНС открытые данные ССЧР (ДатаСост 31.12.2025; набор 7707329152-sshr2019) | R29: ЕГРЮЛ / egrul.nalog.ru (выписка) | S29: 1 | T29: 1 — Горячий | U29: ОКВЭД + 22+ | V29: Да | W29: Да | X29: Да
A30: 804691216 | B30: Общество с ограниченной ответственностью СК "Квадр" | C30: 3812057366 | D30: 3812057366 | E30: ЮЛ РФ | F30: со сбисом работать будут | G30: 20 | H30: 2025 | K30: Нет | L30: Не определено | M30: До 25 | N30: 8400 | O30: 16–30 | P30: ССЧР обогащена; ОКВЭД не найден/не загружен | Q30: ФНС открытые данные ССЧР (ДатаСост 31.12.2025; набор 7707329152-sshr2019) | R30: =HYPERLINK("https://checko.ru/search?query=3801001629","Чекко: проверить") | S30: 1 | T30: 4 — Не обогащён | U30: Нет ОКВЭД/ССЧР | V30: Не определено | W30: Нет
A31: 802410988 | B31: ООО "МОНОЛИТСТРОЙ" | C31: 3811042751 | D31: 3811042751 | E31: ЮЛ РФ | F31: ндз, не будут исп этрн | G31: 34 | H31: 2025 | I31: 41.20 | J31: 41.20; 42.11; 42.21; 42.91; 42.99; 43.11; 43.12.3; 43.13; 43.21; 43.22; 43.29; 43.31; 43.32; 43.33; 43.34; 43.34.1; 43.34.2; 43.39; 43.91; 43.99; 43.99.1; 43.99.2; 43.99.3; 43.99.4; 43.99.5; 43.99.6; 43.99.7; 43.99.9 | K31: Да | L31: Да | M31: До 50 | N31: 16800 | O31: 31–50 | P31: ССЧР + ОКВЭД обогащены | Q31: ФНС открытые данные ССЧР (ДатаСост 31.12.2025; набор 7707329152-sshr2019) | R31: ЕГРЮЛ / egrul.nalog.ru (выписка) | S31: 1 | T31: 1 — Горячий | U31: ОКВЭД + 22+ | V31: Да | W31: Да | X31: Да
A32: 9889001 | B32: Аква-Эко | C32: 382700186 | D32: 3827001863 | E32: ЮЛ РФ | F32: завтра перезвонить, наехали и сброс | G32: 19 | H32: 2025 | K32: Нет | L32: Не определено | M32: До 25 | N32: 8400 | O32: 16–30 | P32: ССЧР обогащена; ОКВЭД не найден/не загружен | Q32: ФНС открытые данные ССЧР (ДатаСост 31.12.2025; набор 7707329152-sshr2019) | R32: =HYPERLINK("https://checko.ru/search?query=3801001629","Чекко: проверить") | S32: 1 | T32: 4 — Не обогащён | U32: Нет ОКВЭД/ССЧР | V32: Не определено | W32: Нет
A33: 9177641 | B33: Шелеховэлектротехмонтаж, ООО | C33: 3821012957 | D33: 3821012957 | E33: ЮЛ РФ | F33: не работают с тр.накладными | G33: 45 | H33: 2025 | I33: 43.21 | J33: 43.21 | K33: Да | L33: Да | M33: До 50 | N33: 16800 | O33: 31–50 | P33: ССЧР + ОКВЭД обогащены | Q33: ФНС открытые данные ССЧР (ДатаСост 31.12.2025; набор 7707329152-sshr2019) | R33: ЕГРЮЛ / egrul.nalog.ru (выписка) | S33: 1 | T33: 1 — Горячий | U33: ОКВЭД + 22+ | V33: Да | W33: Да | X33: Да
A34: 800484337 | B34: Ингео | C34: 3812020373 | D34: 3812020373 | E34: ЮЛ РФ | F34: оквед не тот | G34: 30 | H34: 2025 | I34: 01.61 | J34: 01.61; 43.13; 46.90; 71.12.5; 71.12.6; 72.19 | K34: Да | L34: Да | M34: До 50 | N34: 16800 | O34: 16–30 | P34: ССЧР + ОКВЭД обогащены | Q34: ФНС открытые данные ССЧР (ДатаСост 31.12.2025; набор 7707329152-sshr2019) | R34: ЕГРЮЛ / egrul.nalog.ru (выписка) | S34: 1 | T34: 1 — Горячий | U34: ОКВЭД + 22+ | V34: Да | W34: Да | X34: Да
A35: 800514082 | B35: ООО "ГрузМастер ООО" | C35: 3818026780 | D35: 3818026780 | E35: ЮЛ РФ | F35: ндз, ликвидируют компанию | G35: 1 | H35: 2025 | K35: Нет | L35: Не определено | M35: До 10 | N35: 3360 | O35: 1–15 | P35: ССЧР обогащена; ОКВЭД не найден/не загружен | Q35: ФНС открытые данные ССЧР (ДатаСост 31.12.2025; набор 7707329152-sshr2019) | R35: =HYPERLINK("https://checko.ru/search?query=3801001629","Чекко: проверить") | S35: 1 | T35: 4 — Не обогащён | U35: Нет ОКВЭД/ССЧР | V35: Не определено | W35: Нет
A36: 800834171 | B36: ООО СЗ "ГОРОЖАНЕ" | C36: 3849067610 | D36: 3849067610 | E36: ЮЛ РФ | F36: ндз1 | G36: 4 | H36: 2025 | K36: Нет | L36: Не определено | M36: До 10 | N36: 3360 | O36: 1–15 | P36: ССЧР обогащена; ОКВЭД не найден/не загружен | Q36: ФНС открытые данные ССЧР (ДатаСост 31.12.2025; набор 7707329152-sshr2019) | R36: =HYPERLINK("https://checko.ru/search?query=3801001629","Чекко: проверить") | S36: 1 | T36: 4 — Не обогащён | U36: Нет ОКВЭД/ССЧР | V36: Не определено | W36: Нет
A37: 9114190 | B37: АО "СТОМАТОЛОГИЧЕСКИЙ ЦЕНТР" | C37: 3808128864 | D37: 3808128864 | E37: ЮЛ РФ | F37: некогда вообще | G37: 90 | H37: 2025 | I37: 16.10.9 | J37: 16.10.9; 16.23; 16.24; 16.29; 43.12; 43.99; 47.73; 47.74; 47.75; 47.79; 56.29 | K37: Да | L37: Да | M37: До 100 | N37: 33600 | O37: 51–100 | P37: ССЧР + ОКВЭД обогащены | Q37: ФНС открытые данные ССЧР (ДатаСост 31.12.2025; набор 7707329152-sshr2019) | R37: ЕГРЮЛ / egrul.nalog.ru (выписка) | S37: 1 | T37: 1 — Горячий | U37: ОКВЭД + 22+ | V37: Да | W37: Да | X37: Да
A38: 800848640 | B38: ИП Ковалёв Дмитрий Витальевич | C38: 381113998503 | D38: 381113998503 | E38: ИП РФ / физлицо | F38: поговорили, она рассмотрит кп и даст ответ сама | L38: Не определено | P38: Требует обогащения | Q38: =HYPERLINK("https://pb.nalog.ru/search.html?query=381113998503","ФНС: проверить") | R38: =HYPERLINK("https://checko.ru/search?query=3801001629","Чекко: проверить") | S38: 1 | T38: 4 — Не обогащён | U38: Нет ОКВЭД/ССЧР | V38: Не определено
A39: 9129330 | B39: ООО АБ Мегаполис | C39: 3810072055 | D39: 3810072055 | E39: ЮЛ РФ | F39: не работают с тр.накл | G39: 13 | H39: 2025 | K39: Нет | L39: Не определено | M39: До 25 | N39: 8400 | O39: 1–15 | P39: ССЧР обогащена; ОКВЭД не найден/не загружен | Q39: ФНС открытые данные ССЧР (ДатаСост 31.12.2025; набор 7707329152-sshr2019) | R39: =HYPERLINK("https://checko.ru/search?query=3801001629","Чекко: проверить") | S39: 1 | T39: 4 — Не обогащён | U39: Нет ОКВЭД/ССЧР | V39: Не определено | W39: Нет
A40: 800767960 | B40: ВСКР ООО ТПК | C40: 3811470764 | D40: 3811470764 | E40: ЮЛ РФ | F40: негативные контакты и ндз | G40: 34 | H40: 2025 | I40: 46.90 | J40: 46.90; 22.22; 45.31.1; 46.49.43; 46.73; 49.41.3 | K40: Да | L40: Да | M40: До 50 | N40: 16800 | O40: 31–50 | P40: ССЧР + ОКВЭД обогащены | Q40: ФНС открытые данные ССЧР (ДатаСост 31.12.2025; набор 7707329152-sshr2019) | R40: ЕГРЮЛ / egrul.nalog.ru (выписка) | S40: 1 | T40: 1 — Горячий | U40: ОКВЭД + 22+ | V40: Да | W40: Да | X40: Да
...

Sheet 06_Горячие_клиенты
A1: Горячие клиенты — ежедневная работа отдела продаж
A2: Критерии: целевой ОКВЭД + 22+ сотрудников, либо 50+, либо приоритет «1 — Горячий». Заполните ответственного и статусы (зелёные). | E2: Записей: 345
A4: ИНН | B4: Компания | C4: Основной ОКВЭД | D4: ССЧР | E4: Приоритет | F4: Потенциал ₽/год | G4: Ответственный менеджер | H4: Дата обработки | I4: Статус | J4: Следующий контакт | K4: Комментарий
A5: 3808224590 | B5: ООО "БайкалВЭД" | C5: 16.23 | D5: 22 | E5: 1 — Горячий | F5: 8400 | G5: Оглоблина | I5: В работе | K5: со сбисом
A6: 3814019503 | B6: ООО "ДЭП №153" | C6: 42.11 | D6: 221 | E6: 1 — Горячий | F6: 144000 | G6: Юнусова | I6: В работе | K6: не работают с трн
A7: 3814008565 | B7: ООО "Саянск-Лифт" | C7: 43.29 | D7: 25 | E7: 1 — Горячий | F7: 8400 | G7: Кургузов | I7: В работе | K7: ответили на почту отпр, свяжутся сами
A8: 3818043360 | B8: ООО "ТЕРМИНАЛ ЛЕНАРЕЧТРАНС" | C8: 50.40.1 | D8: 248 | E8: 1 — Горячий | F8: 144000 | G8: Оглоблина | I8: В работе | K8: у них контур логистика
A9: 3804042888 | B9: ООО "Электро Мотор Ремонт" | C9: 33.14 | D9: 23 | E9: 1 — Горячий | F9: 8400 | G9: Юнусова | I9: В работе | K9: оквед не тот
A10: 3827014037 | B10: ООО "СТАТУССИБ" | C10: 42.11 | D10: 433 | E10: 1 — Горячий | F10: 144000 | G10: Кургузов | I10: В работе | K10: перезвонить марианне, выставила счет
A11: 3811042751 | B11: ООО "МОНОЛИТСТРОЙ" | C11: 41.20 | D11: 34 | E11: 1 — Горячий | F11: 16800 | G11: Оглоблина | I11: В работе | K11: ндз, не будут исп этрн
A12: 3821012957 | B12: Шелеховэлектротехмонтаж, ООО | C12: 43.21 | D12: 45 | E12: 1 — Горячий | F12: 16800 | G12: Юнусова | I12: В работе | K12: не работают с тр.накладными
A13: 3812020373 | B13: Ингео | C13: 01.61 | D13: 30 | E13: 1 — Горячий | F13: 16800 | G13: Кургузов | I13: В работе | K13: оквед не тот
A14: 3808128864 | B14: АО "СТОМАТОЛОГИЧЕСКИЙ ЦЕНТР" | C14: 16.10.9 | D14: 90 | E14: 1 — Горячий | F14: 33600 | G14: Оглоблина | I14: В работе | K14: некогда вообще
A15: 3811470764 | B15: ВСКР ООО ТПК | C15: 46.90 | D15: 34 | E15: 1 — Горячий | F15: 16800 | G15: Юнусова | I15: В работе | K15: негативные контакты и ндз
A16: 3816013458 | B16: Общество с ограниченной ответственностью "Буровзрывные работы" | C16: 43.12.4 | D16: 37 | E16: 1 — Горячий | F16: 16800 | G16: Кургузов | I16: В работе
A17: 3808142604 | B17: Русичи Трейд, ООО | C17: 46.90 | D17: 69 | E17: 1 — Горячий | F17: 33600 | G17: Оглоблина | I17: В работе
A18: 7726284852 | B18: ОБЩЕСТВО С ОГРАНИЧЕННОЙ ОТВЕТСТВЕННОСТЬЮ "ЧИСТОЗОР" | C18: 25.99.11 | D18: 32 | E18: 1 — Горячий | F18: 16800 | G18: Юнусова | I18: В работе
A19: 3849011054 | B19: Геоконтроль-Восток, ООО | C19: 71.12.3 | D19: 125 | E19: 1 — Горячий | F19: 62400 | G19: Кургузов | I19: В работе
A20: 3805700280 | B20: Общество с ограниченной ответственностью "ТРАНССТРОЙ" | C20: 42.11 | D20: 24 | E20: 1 — Горячий | F20: 8400 | G20: Оглоблина | I20: В работе
A21: 3818014880 | B21: ОАО "Алроса-Терминал" | C21: 52.24.2 | D21: 147 | E21: 1 — Горячий | F21: 62400 | G21: Юнусова | I21: В работе
A22: 3810035293 | B22: Типография ИРКУТ | C22: 18.12.9 | D22: 44 | E22: 1 — Горячий | F22: 16800 | G22: Кургузов | I22: В работе
A23: 3827024814 | B23: ООО "АЙХАЛ" | C23: 15.20 | D23: 64 | E23: 1 — Горячий | F23: 33600 | G23: Оглоблина | I23: В работе
A24: 3811070942 | B24: ООО "СибМАП" | C24: 45.20.2 | D24: 23 | E24: 1 — Горячий | F24: 8400 | G24: Юнусова | I24: В работе
A25: 3808156861 | B25: Лесресурс, ООО | C25: 16.10.1 | D25: 29 | E25: 1 — Горячий | F25: 16800 | G25: Кургузов | I25: В работе
A26: 3812079345 | B26: ООО "Янтарь" | C26: 47.22 | D26: 347 | E26: 1 — Горячий | F26: 144000 | G26: Оглоблина | I26: В работе
A27: 3808133543 | B27: ООО "Сибирская Легкая Авиация" | C27: 51.10.1 | D27: 107 | E27: 1 — Горячий | F27: 62400 | G27: Юнусова | I27: В работе
... A177: 3808218155 | B177: ЗАО "НИПИИ Восток" | C177: 09.10.3 | D177: 30 | E177: 1 — Горячий | F177: 16800 | G177: Юнусова | I177: В работе
A178: 3812010801 | B178: Акционерное общество "КЛИНИЧЕСКИЙ КУРОРТ "АНГАРА" | D178: 160 | E178: 1 — Горячий | F178: 62400 | G178: Кургузов | I178: В работе
A179: 1434033057 | B179: Нерюнгринская жилищная компания | C179: 68.32 | D179: 24 | E179: 1 — Горячий | F179: 8400 | G179: Оглоблина | I179: В работе
A180: 3811462996 | B180: ОБЩЕСТВО С ОГРАНИЧЕННОЙ ОТВЕТСТВЕННОСТЬЮ "ТАЙРИКУ-ИГИРМА ГРУПП" | C180: 16.10.1 | D180: 739 | E180: 1 — Горячий | F180: 528000 | G180: Юнусова | I180: В работе
A181: 3808220108 | B181: ООО "ЭДЕЛЬВЕЙС" ДИАЙ КЛИНИК" | C181: 86.23 | D181: 62 | E181: 1 — Горячий | F181: 33600 | G181: Кургузов | I181: В работе
A182: 3849012499 | B182: СТРОЙ-РЕСУРС | C182: 43.12 | D182: 54 | E182: 1 — Горячий | F182: 33600 | G182: Оглоблина | I182: В работе
A183: 3815003200 | B183: Парчумлес | C183: 02.20 | D183: 44 | E183: 1 — Горячий | F183: 16800 | G183: Юнусова | I183: В работе
A184: 3816014606 | B184: ООО "Супер" | C184: 47.25.1 | D184: 26 | E184: 1 — Горячий | F184: 16800 | G184: Кургузов | I184: В работе
A185: 3849023959 | B185: ООО "Трансуголь" | C185: 05.10.11 | D185: 44 | E185: 1 — Горячий | F185: 16800 | G185: Оглоблина | I185: В работе
A186: 3808070237 | B186: Охранное Агентство БАБР, ООО | C186: 80.10 | D186: 33 | E186: 1 — Горячий | F186: 16800 | G186: Юнусова | I186: В работе
A187: 3827010850 | B187: ООО "АгроСмоленское" | C187: 01.13.1 | D187: 25 | E187: 1 — Горячий | F187: 8400 | G187: Кургузов | I187: В работе
A188: 3808079832 | B188: Гранд Байкал ВИП | C188: 86.90.4 | D188: 445 | E188: 1 — Горячий | F188: 144000 | G188: Оглоблина | I188: В работе
A189: 3815008575 | B189: ООО «Прогресс» | C189: 02.20 | D189: 33 | E189: 1 — Горячий | F189: 16800 | G189: Юнусова | I189: В работе
A190: 2700020905 | B190: ОБЩЕСТВО С ОГРАНИЧЕННОЙ ОТВЕТСТВЕННОСТЬЮ "ИТ СОВА" | C190: 63.11.1 | D190: 90 | E190: 1 — Горячий | F190: 33600 | G190: Кургузов | I190: В работе
...

Sheet 07_План_продаж
A1: План продаж — сценарии 4 / 6 / 9 и воронка по источникам
A2: Прогноз воронки (гипотеза) и коммерческий план — разные показатели. Excel показывает разрыв и требуемую конверсию.
A4: Сценарий | B4: Лидов/мес | C4: → переговоры | D4: → демо | E4: → сделка | F4: → оплата | G4: Общая конв. | H4: Прогноз оплат | I4: Целевые продажи | J4: Требуемая конв. для плана | K4: Лидов для плана при текущей конв. | L4: Выручка по плану | M4: Маржа по плану | N4: Премия по плану
A5: Малый | B5: ='01_Исходные_данные'!B14 | C5: ='01_Исходные_данные'!B15 | D5: ='01_Исходные_данные'!B16 | E5: ='01_Исходные_данные'!B17 | F5: ='01_Исходные_данные'!B18 | G5: =C5*D5*E5*F5 | H5: =B5*G5 | I5: ='01_Исходные_данные'!B20 | J5: =IF(B5=0,0,I5/B5) | K5: =IF(G5=0,0,I5/G5) | L5: =I5*'01_Исходные_данные'!B5 | M5: =I5*'01_Исходные_данные'!B7 | N5: =M5*'01_Исходные_данные'!B24
A6: Средний | B6: ='01_Исходные_данные'!C14 | C6: ='01_Исходные_данные'!C15 | D6: ='01_Исходные_данные'!C16 | E6: ='01_Исходные_данные'!C17 | F6: ='01_Исходные_данные'!C18 | G6: =C6*D6*E6*F6 | H6: =B6*G6 | I6: ='01_Исходные_данные'!C20 | J6: =IF(B6=0,0,I6/B6) | K6: =IF(G6=0,0,I6/G6) | L6: =I6*'01_Исходные_данные'!B5 | M6: =I6*'01_Исходные_данные'!B7 | N6: =M6*'01_Исходные_данные'!C24
A7: Большой | B7: ='01_Исходные_данные'!D14 | C7: ='01_Исходные_данные'!D15 | D7: ='01_Исходные_данные'!D16 | E7: ='01_Исходные_данные'!D17 | F7: ='01_Исходные_данные'!D18 | G7: =C7*D7*E7*F7 | H7: =B7*G7 | I7: ='01_Исходные_данные'!D20 | J7: =IF(B7=0,0,I7/B7) | K7: =IF(G7=0,0,I7/G7) | L7: =I7*'01_Исходные_данные'!B5 | M7: =I7*'01_Исходные_данные'!B7 | N7: =M7*'01_Исходные_данные'!D24
A9: План команды
A10: Сценарий | B10: Менеджеров | C10: Продаж/мес | D10: Выручка/мес | E10: Маржа/мес | F10: Премии/мес | G10: Оклады/мес | H10: Результат до прочих
A11: =A5 | B11: ='01_Исходные_данные'!B31 | C11: =I5*B11 | D11: =L5*B11 | E11: =M5*B11 | F11: =N5*B11 | G11: ='01_Исходные_данные'!B32 | H11: =E11-F11-G11
A12: =A6 | B12: ='01_Исходные_данные'!B31 | C12: =I6*B12 | D12: =L6*B12 | E12: =M6*B12 | F12: =N6*B12 | G12: ='01_Исходные_данные'!B32 | H12: =E12-F12-G12
A13: =A7 | B13: ='01_Исходные_данные'!B31 | C13: =I7*B13 | D13: =L7*B13 | E13: =M7*B13 | F13: =N7*B13 | G13: ='01_Исходные_данные'!B32 | H13: =E13-F13-G13
A15: Воронка по источникам базы (план/модель)
A16: Источник | B16: Обработано | C16: Переговоры | D16: Демо | E16: Сделки | F16: Оплаты | G16: Общая конв. | H16: Выручка | I16: Маржа
A17: Наша база | B17: 350 | C17: =ROUND(B17*'01_Исходные_данные'!C15,0) | D17: =ROUND(C17*'01_Исходные_данные'!C16,0) | E17: =ROUND(D17*'01_Исходные_данные'!C17,0) | F17: =ROUND(E17*'01_Исходные_данные'!C18,0) | G17: =IF(B17=0,0,F17/B17) | H17: =F17*'01_Исходные_данные'!B5 | I17: =F17*'01_Исходные_данные'!B7
A18: ОКВЭД | B18: 0 | C18: 0 | D18: 0 | E18: 0 | F18: 0 | G18: =IF(B18=0,0,F18/B18) | H18: =F18*'01_Исходные_данные'!B5 | I18: =F18*'01_Исходные_данные'!B7
A19: Лекторий | B19: 0 | C19: 0 | D19: 0 | E19: 0 | F19: 0 | G19: =IF(B19=0,0,F19/B19) | H19: =F19*'01_Исходные_данные'!B5 | I19: =F19*'01_Исходные_данные'!B7
A20: Входящие | B20: 0 | C20: 0 | D20: 0 | E20: 0 | F20: 0 | G20: =IF(B20=0,0,F20/B20) | H20: =F20*'01_Исходные_данные'!B5 | I20: =F20*'01_Исходные_данные'!B7
A21: Партнёры | B21: 0 | C21: 0 | D21: 0 | E21: 0 | F21: 0 | G21: =IF(B21=0,0,F21/B21) | H21: =F21*'01_Исходные_данные'!B5 | I21: =F21*'01_Исходные_данные'!B7
A22: Реклама | B22: 0 | C22: 0 | D22: 0 | E22: 0 | F22: 0 | G22: =IF(B22=0,0,F22/B22) | H22: =F22*'01_Исходные_данные'!B5 | I22: =F22*'01_Исходные_данные'!B7
A24: Итого по источникам | B24: =SUM(B17:B22) | C24: =SUM(C17:C22) | D24: =SUM(D17:D22) | E24: =SUM(E17:E22) | F24: =SUM(F17:F22) | G24: =IF(B24=0,0,F24/B24) | H24: =SUM(H17:H22) | I24: =SUM(I17:I22)
A26: Стоимость продажи (по среднему сценарию команды) | B26: =IF(C12=0,0,('01_Исходные_данные'!B32+'01_Исходные_данные'!B33+'01_Исходные_данные'!B34+'01_Исходные_данные'!B35)/C12) | C26: ₽ на 1 оплату (оклады+прочие)/продажи

Sheet 08_Факт_воронка
A1: Факт продаж и воронка
A2: Вводите только зелёные поля. Конверсии, выполнение плана, маржа — считаются автоматически и уходят в P&L / ДДС / Dashboard.
A4: Менеджер | B4: Сценарий плана | C4: План продаж | D4: Обработано | E4: Переговоры | F4: Демо | G4: Сделки | H4: Оплаты | I4: Конв. → перег. | J4: Конв. → демо | K4: Конв. → сделка | L4: Конв. → оплата | M4: Общая конв. | N4: Выполнение плана | O4: Выручка | P4: Маржа | Q4: Премия
A5: ='01_Исходные_данные'!A28 | B5: Средний | C5: =IF(B5="Малый",'01_Исходные_данные'!$B$20,IF(B5="Средний",'01_Исходные_данные'!$C$20,'01_Исходные_данные'!$D$20)) | D5: 0 | E5: 0 | F5: 0 | G5: 0 | H5: 0 | I5: =IF(D5=0,0,E5/D5) | J5: =IF(E5=0,0,F5/E5) | K5: =IF(F5=0,0,G5/F5) | L5: =IF(G5=0,0,H5/G5) | M5: =IF(D5=0,0,H5/D5) | N5: =IF(C5=0,0,H5/C5) | O5: =H5*'01_Исходные_данные'!$B$5 | P5: =H5*'01_Исходные_данные'!$B$7 | Q5: =P5*IF(B5="Малый",'01_Исходные_данные'!$B$24,IF(B5="Средний",'01_Исходные_данные'!$C$24,'01_Исходные_данные'!$D$24))
A6: ='01_Исходные_данные'!A29 | B6: Средний | C6: =IF(B6="Малый",'01_Исходные_данные'!$B$20,IF(B6="Средний",'01_Исходные_данные'!$C$20,'01_Исходные_данные'!$D$20)) | D6: 0 | E6: 0 | F6: 0 | G6: 0 | H6: 0 | I6: =IF(D6=0,0,E6/D6) | J6: =IF(E6=0,0,F6/E6) | K6: =IF(F6=0,0,G6/F6) | L6: =IF(G6=0,0,H6/G6) | M6: =IF(D6=0,0,H6/D6) | N6: =IF(C6=0,0,H6/C6) | O6: =H6*'01_Исходные_данные'!$B$5 | P6: =H6*'01_Исходные_данные'!$B$7 | Q6: =P6*IF(B6="Малый",'01_Исходные_данные'!$B$24,IF(B6="Средний",'01_Исходные_данные'!$C$24,'01_Исходные_данные'!$D$24))
A7: ='01_Исходные_данные'!A30 | B7: Средний | C7: =IF(B7="Малый",'01_Исходные_данные'!$B$20,IF(B7="Средний",'01_Исходные_данные'!$C$20,'01_Исходные_данные'!$D$20)) | D7: 0 | E7: 0 | F7: 0 | G7: 0 | H7: 0 | I7: =IF(D7=0,0,E7/D7) | J7: =IF(E7=0,0,F7/E7) | K7: =IF(F7=0,0,G7/F7) | L7: =IF(G7=0,0,H7/G7) | M7: =IF(D7=0,0,H7/D7) | N7: =IF(C7=0,0,H7/C7) | O7: =H7*'01_Исходные_данные'!$B$5 | P7: =H7*'01_Исходные_данные'!$B$7 | Q7: =P7*IF(B7="Малый",'01_Исходные_данные'!$B$24,IF(B7="Средний",'01_Исходные_данные'!$C$24,'01_Исходные_данные'!$D$24))
A8: ИТОГО | C8: =SUM(C5:C7) | D8: =SUM(D5:D7) | E8: =SUM(E5:E7) | F8: =SUM(F5:F7) | G8: =SUM(G5:G7) | H8: =SUM(H5:H7) | I8: =IF(D8=0,0,E8/D8) | J8: =IF(E8=0,0,F8/E8) | K8: =IF(F8=0,0,G8/F8) | L8: =IF(G8=0,0,H8/G8) | M8: =IF(D8=0,0,H8/D8) | N8: =IF(C8=0,0,H8/C8) | O8: =SUM(O5:O7) | P8: =SUM(P5:P7) | Q8: =SUM(Q5:Q7)
A10: Факт по источникам
A11: Источник | B11: Обработано | C11: Переговоры | D11: Демо | E11: Сделки | F11: Оплаты | G11: Общая конв. | H11: Выручка | I11: Маржа
A12: Наша база | B12: 0 | C12: 0 | D12: 0 | E12: 0 | F12: 0 | G12: =IF(B12=0,0,F12/B12) | H12: =F12*'01_Исходные_данные'!$B$5 | I12: =F12*'01_Исходные_данные'!$B$7
A13: ОКВЭД | B13: 0 | C13: 0 | D13: 0 | E13: 0 | F13: 0 | G13: =IF(B13=0,0,F13/B13) | H13: =F13*'01_Исходные_данные'!$B$5 | I13: =F13*'01_Исходные_данные'!$B$7
A14: Лекторий | B14: 0 | C14: 0 | D14: 0 | E14: 0 | F14: 0 | G14: =IF(B14=0,0,F14/B14) | H14: =F14*'01_Исходные_данные'!$B$5 | I14: =F14*'01_Исходные_данные'!$B$7
A15: Входящие | B15: 0 | C15: 0 | D15: 0 | E15: 0 | F15: 0 | G15: =IF(B15=0,0,F15/B15) | H15: =F15*'01_Исходные_данные'!$B$5 | I15: =F15*'01_Исходные_данные'!$B$7
A16: Партнёры | B16: 0 | C16: 0 | D16: 0 | E16: 0 | F16: 0 | G16: =IF(B16=0,0,F16/B16) | H16: =F16*'01_Исходные_данные'!$B$5 | I16: =F16*'01_Исходные_данные'!$B$7
A17: Реклама | B17: 0 | C17: 0 | D17: 0 | E17: 0 | F17: 0 | G17: =IF(B17=0,0,F17/B17) | H17: =F17*'01_Исходные_данные'!$B$5 | I17: =F17*'01_Исходные_данные'!$B$7
A19: Контроль: сумма оплат по менеджерам должна сходиться с суммой оплат по источникам (если ведёте оба разреза).
A20: Оплаты менеджеры | B20: =H8
A21: Оплаты источники | B21: =SUM(F12:F17)
A22: Расхождение | B22: =B20-B21

Sheet 09_PnL
A1: Финансовый план (P&L) — экономика проекта
A2: План по сценариям и факт месяца. Налоги/взносы в текущей версии не моделируются.
A4: Статья | B4: Малый план | C4: Средний план | D4: Большой план | E4: Факт месяца | F4: Комментарий
A5: Выручка | B5: ='07_План_продаж'!D11 | C5: ='07_План_продаж'!D12 | D5: ='07_План_продаж'!D13 | E5: ='08_Факт_воронка'!O8 | F5: Оплаты × цена
A6: Себестоимость (закупка 1С) | B6: =-B5*'01_Исходные_данные'!B6/'01_Исходные_данные'!B5 | C6: =-C5*'01_Исходные_данные'!B6/'01_Исходные_данные'!B5 | D6: =-D5*'01_Исходные_данные'!B6/'01_Исходные_данные'!B5 | E6: =-E5*'01_Исходные_данные'!B6/'01_Исходные_данные'!B5 | F6: Пропорция закупки
A7: Маржинальный доход | B7: =B5+B6 | C7: =C5+C6 | D7: =D5+D6 | E7: =E5+E6 | F7: После закупки
A8: ФОТ (оклады) | B8: =-'01_Исходные_данные'!B32 | C8: =-'01_Исходные_данные'!B32 | D8: =-'01_Исходные_данные'!B32 | E8: =-'01_Исходные_данные'!B32 | F8: Активные менеджеры
A9: Премии | B9: =-'07_План_продаж'!F11 | C9: =-'07_План_продаж'!F12 | D9: =-'07_План_продаж'!F13 | E9: =-'08_Факт_воронка'!Q8 | F9: % от маржи
A10: Маркетинг | B10: =-'01_Исходные_данные'!B33 | C10: =-'01_Исходные_данные'!B33 | D10: =-'01_Исходные_данные'!B33 | E10: =-'01_Исходные_данные'!B33
A11: Техподдержка | B11: =-'01_Исходные_данные'!B34 | C11: =-'01_Исходные_данные'!B34 | D11: =-'01_Исходные_данные'!B34 | E11: =-'01_Исходные_данные'!B34
A12: Прочие расходы | B12: =-'01_Исходные_данные'!B35 | C12: =-'01_Исходные_данные'!B35 | D12: =-'01_Исходные_данные'!B35 | E12: =-'01_Исходные_данные'!B35
A13: Операционная прибыль | B13: =B7+B8+B9+B10+B11+B12 | C13: =C7+C8+C9+C10+C11+C12 | D13: =D7+D8+D9+D10+D11+D12 | E13: =E7+E8+E9+E10+E11+E12 | F13: До налогов
A14: Маржинальность (маржа/выручка) | B14: =IF(B5=0,0,B7/B5) | C14: =IF(C5=0,0,C7/C5) | D14: =IF(D5=0,0,D7/D5) | E14: =IF(E5=0,0,E7/E5)
A15: Рентабельность (прибыль/выручка) | B15: =IF(B5=0,0,B13/B5) | C15: =IF(C5=0,0,C13/C5) | D15: =IF(D5=0,0,D13/D5) | E15: =IF(E5=0,0,E13/E5)

Sheet 10_ДДС
A1: ДДС проекта — когда выходим в плюс
A2: Годовая подписка поступает разово при оплате. Ниже: сценарии плана и помесячный ДДС среднего сценария на 12 месяцев.
A4: Сводка по сценариям (месяц в стационаре)
A5: Сценарий | B5: Оплат / мес. | C5: Поступления | D5: Закупка 1С | E5: Оклады | F5: Премии | G5: Прочие | H5: Денежный поток | I5: Годовой поток
A6: Малый | B6: ='07_План_продаж'!C11 | C6: =B6*'01_Исходные_данные'!B5 | D6: =B6*'01_Исходные_данные'!B6 | E6: ='01_Исходные_данные'!B32 | F6: ='07_План_продаж'!F11 | G6: ='01_Исходные_данные'!B33+'01_Исходные_данные'!B34+'01_Исходные_данные'!B35 | H6: =C6-D6-E6-F6-G6 | I6: =H6*12
A7: Средний | B7: ='07_План_продаж'!C12 | C7: =B7*'01_Исходные_данные'!B5 | D7: =B7*'01_Исходные_данные'!B6 | E7: ='01_Исходные_данные'!B32 | F7: ='07_План_продаж'!F12 | G7: ='01_Исходные_данные'!B33+'01_Исходные_данные'!B34+'01_Исходные_данные'!B35 | H7: =C7-D7-E7-F7-G7 | I7: =H7*12
A8: Большой | B8: ='07_План_продаж'!C13 | C8: =B8*'01_Исходные_данные'!B5 | D8: =B8*'01_Исходные_данные'!B6 | E8: ='01_Исходные_данные'!B32 | F8: ='07_План_продаж'!F13 | G8: ='01_Исходные_данные'!B33+'01_Исходные_данные'!B34+'01_Исходные_данные'!B35 | H8: =C8-D8-E8-F8-G8 | I8: =H8*12
A10: Точка безубыточности (оплат/мес.) | B10: =IF(('01_Исходные_данные'!B7*(1-'01_Исходные_данные'!C24))=0,0,ROUNDUP(('01_Исходные_данные'!B32+'01_Исходные_данные'!B33+'01_Исходные_данные'!B34+'01_Исходные_данные'!B35)/('01_Исходные_данные'!B7*(1-'01_Исходные_данные'!C24)),0)) | C10: При средней премии 30%; без налогов
A12: Помесячный ДДС — средний сценарий (12 мес.)
A13: Месяц | B13: 1 | C13: 2 | D13: 3 | E13: 4 | F13: 5 | G13: 6 | H13: 7 | I13: 8 | J13: 9 | K13: 10 | L13: 11 | M13: 12
A14: Коэффициент выхода | B14: 0.4 | C14: 0.6 | D14: 0.8 | E14: 1 | F14: 1 | G14: 1 | H14: 1 | I14: 1 | J14: 1 | K14: 1 | L14: 1 | M14: 1
A15: Поступления | B15: ='07_План_продаж'!D12*B14 | C15: ='07_План_продаж'!D12*C14 | D15: ='07_План_продаж'!D12*D14 | E15: ='07_План_продаж'!D12*E14 | F15: ='07_План_продаж'!D12*F14 | G15: ='07_План_продаж'!D12*G14 | H15: ='07_План_продаж'!D12*H14 | I15: ='07_План_продаж'!D12*I14 | J15: ='07_План_продаж'!D12*J14 | K15: ='07_План_продаж'!D12*K14 | L15: ='07_План_продаж'!D12*L14 | M15: ='07_План_продаж'!D12*M14
A16: Закупка 1С | B16: ='07_План_продаж'!D12*'01_Исходные_данные'!B6/'01_Исходные_данные'!B5*B14 | C16: ='07_План_продаж'!D12*'01_Исходные_данные'!B6/'01_Исходные_данные'!B5*C14 | D16: ='07_План_продаж'!D12*'01_Исходные_данные'!B6/'01_Исходные_данные'!B5*D14 | E16: ='07_План_продаж'!D12*'01_Исходные_данные'!B6/'01_Исходные_данные'!B5*E14 | F16: ='07_План_продаж'!D12*'01_Исходные_данные'!B6/'01_Исходные_данные'!B5*F14 | G16: ='07_План_продаж'!D12*'01_Исходные_данные'!B6/'01_Исходные_данные'!B5*G14 | H16: ='07_План_продаж'!D12*'01_Исходные_данные'!B6/'01_Исходные_данные'!B5*H14 | I16: ='07_План_продаж'!D12*'01_Исходные_данные'!B6/'01_Исходные_данные'!B5*I14 | J16: ='07_План_продаж'!D12*'01_Исходные_данные'!B6/'01_Исходные_данные'!B5*J14 | K16: ='07_План_продаж'!D12*'01_Исходные_данные'!B6/'01_Исходные_данные'!B5*K14 | L16: ='07_План_продаж'!D12*'01_Исходные_данные'!B6/'01_Исходные_данные'!B5*L14 | M16: ='07_План_продаж'!D12*'01_Исходные_данные'!B6/'01_Исходные_данные'!B5*M14
A17: Оклады | B17: ='01_Исходные_данные'!B32 | C17: ='01_Исходные_данные'!B32 | D17: ='01_Исходные_данные'!B32 | E17: ='01_Исходные_данные'!B32 | F17: ='01_Исходные_данные'!B32 | G17: ='01_Исходные_данные'!B32 | H17: ='01_Исходные_данные'!B32 | I17: ='01_Исходные_данные'!B32 | J17: ='01_Исходные_данные'!B32 | K17: ='01_Исходные_данные'!B32 | L17: ='01_Исходные_данные'!B32 | M17: ='01_Исходные_данные'!B32
A18: Премии | B18: ='07_План_продаж'!F12*B14 | C18: ='07_План_продаж'!F12*C14 | D18: ='07_План_продаж'!F12*D14 | E18: ='07_План_продаж'!F12*E14 | F18: ='07_План_продаж'!F12*F14 | G18: ='07_План_продаж'!F12*G14 | H18: ='07_План_продаж'!F12*H14 | I18: ='07_План_продаж'!F12*I14 | J18: ='07_План_продаж'!F12*J14 | K18: ='07_План_продаж'!F12*K14 | L18: ='07_План_продаж'!F12*L14 | M18: ='07_План_продаж'!F12*M14
A19: Прочие расходы | B19: ='01_Исходные_данные'!B33+'01_Исходные_данные'!B34+'01_Исходные_данные'!B35 | C19: ='01_Исходные_данные'!B33+'01_Исходные_данные'!B34+'01_Исходные_данные'!B35 | D19: ='01_Исходные_данные'!B33+'01_Исходные_данные'!B34+'01_Исходные_данные'!B35 | E19: ='01_Исходные_данные'!B33+'01_Исходные_данные'!B34+'01_Исходные_данные'!B35 | F19: ='01_Исходные_данные'!B33+'01_Исходные_данные'!B34+'01_Исходные_данные'!B35 | G19: ='01_Исходные_данные'!B33+'01_Исходные_данные'!B34+'01_Исходные_данные'!B35 | H19: ='01_Исходные_данные'!B33+'01_Исходные_данные'!B34+'01_Исходные_данные'!B35 | I19: ='01_Исходные_данные'!B33+'01_Исходные_данные'!B34+'01_Исходные_данные'!B35 | J19: ='01_Исходные_данные'!B33+'01_Исходные_данные'!B34+'01_Исходные_данные'!B35 | K19: ='01_Исходные_данные'!B33+'01_Исходные_данные'!B34+'01_Исходные_данные'!B35 | L19: ='01_Исходные_данные'!B33+'01_Исходные_данные'!B34+'01_Исходные_данные'!B35 | M19: ='01_Исходные_данные'!B33+'01_Исходные_данные'!B34+'01_Исходные_данные'!B35
A20: Денежный поток | B20: =B15-B16-B17-B18-B19 | C20: =C15-C16-C17-C18-C19 | D20: =D15-D16-D17-D18-D19 | E20: =E15-E16-E17-E18-E19 | F20: =F15-F16-F17-F18-F19 | G20: =G15-G16-G17-G18-G19 | H20: =H15-H16-H17-H18-H19 | I20: =I15-I16-I17-I18-I19 | ... M20: =M15-M16-M17-M18-M19
A21: Накопленный поток | B21: =B20 | C21: =B21+C20 | D21: =C21+D20 | E21: =D21+E20 | F21: =E21+F20 | G21: =F21+G20 | H21: =G21+H20 | I21: =H21+I20 | J21: =I21+J20 | ... M21: =L21+M20
A23: Месяц выхода в плюс (накопленный поток > 0) | B23: =IF(M21>0,MATCH(TRUE,INDEX(B21:M21>0,0),0),"не в горизонте 12 мес.")
A25: Факт месяца (из воронки)
A26: Поступления факт | B26: ='08_Факт_воронка'!O8
A27: Закупка факт | B27: ='08_Факт_воронка'!H8*'01_Исходные_данные'!B6
A28: Оклады | B28: ='01_Исходные_данные'!B32
A29: Премии факт | B29: ='08_Факт_воронка'!Q8
A30: Прочие | B30: ='01_Исходные_данные'!B33+'01_Исходные_данные'!B34+'01_Исходные_данные'!B35
A31: Поток факт | B31: =B26-B27-B28-B29-B30

Sheet 12_Методика
A1: Методика модели — проверяемость для инвестора
A2: Любое число — факт, параметр или расчёт. Гипотезы не смешиваются с фактом воронки.
A4: Показатель | B4: Что означает | C4: Где брать | D4: Тип | E4: Проверка
A5: ИНН | B5: Идентификатор компании | C5: Исходная CRM-база | D5: Факт | E5: Уникальность
A6: ОКВЭД | B6: Отраслевой профиль | C6: ЕГРЮЛ / egrul.nalog.ru | D6: Факт | E6: Дата выписки
A7: ССЧР | B7: Среднесписочная численность | C7: ФНС open data 7707329152-sshr2019 | D7: Факт | E7: Год показателя
A8: Целевой ОКВЭД | B8: ICP проекта | C8: Справочник на листе исходных данных | D8: Правило | E8: Префиксы ОКВЭД
A9: Горячий клиент | B9: ОКВЭД+22+ или 50+ | C9: Расчёт | D9: Расчёт | E9: Оба критерия
A10: Конверсия план | B10: Гипотеза воронки | C10: 01_Исходные_данные | D10: Гипотеза | E10: Не подменять фактом
A11: Конверсия факт | B11: Факт этапов | C11: 08_Факт_воронка | D11: Факт | E11: CRM / 1С
A12: План 4/6/9 | B12: Целевые продажи | C12: Управленческая гипотеза | D12: Гипотеза | E12: Сверять с требуемой конв.
A13: Цена / закупка | B13: Unit-экономика | C13: Прайс 1С | D13: Параметр | E13: Маржа = цена − закупка
A14: Премия | B14: % от маржи | C14: Политика мотивации | D14: Параметр | E14: Не от выручки
A15: TAM/SAM/SOM | B15: Рынок | C15: Федеральные реестры + capacity | D15: Расчёт | E15: SAM ⊂ TAM; SOM ≤ capacity
A16: P&L / ДДС | B16: Экономика и кэш | C16: Авто из плана/факта | D16: Расчёт | E16: Сходимость оплат
A18: Источники обогащения этой версии
A19: 1) ССЧР: https://www.nalog.gov.ru/opendata/7707329152-sshr2019/ (данные за 2025, ДатаСост 31.12.2025).
A20: 2) ОКВЭД: выписки ЕГРЮЛ с egrul.nalog.ru для приоритетного сегмента 22+.
A21: 3) Тарифы: партнёрский прайс «1С:Кабинет сотрудника» (розница/дилер).
A22: Пересборка: python3 scripts/build_investment_model.py
